<mujoco model="ur5_summit">
    <compiler angle="radian" meshdir="assets"/>
    <size njmax="500" nconmax="100" />
    <default>
        <default class="FTsensor">
            <site type="cylinder" size="0.005 0.005" group="4" rgba=".1 .1 .9 1"/>
        </default>
    </default>
    <default>   
        <default class="cls">
                <geom group="1" rgba="0.79216 0.81961 0.93333 0.5"/>
        </default>
    </default>
    <asset>
        <material class="ur5e" name="black" rgba="0.033 0.033 0.033 1"/>
        <material class="ur5e" name="jointgray" rgba="0.278 0.278 0.278 1"/>
        <material class="ur5e" name="linkgray" rgba="0.82 0.82 0.82 1"/>
        <material class="ur5e" name="urblue" rgba="0.49 0.678 0.8 1"/>   

        <mesh name="link0" file="base.stl" />
        <mesh name="link1" file="shoulder.stl" />
        <mesh name="link2" file="upperarm.stl" />
        <mesh name="link3" file="forearm.stl" />
        <mesh name="link4" file="wrist1.stl" />
        <mesh name="link5" file="wrist1.stl" />
        <mesh name="link6" file="wrist2.stl" />
        <mesh name="summit_xls_chassis" file="summit_xls_chassis.stl"/>
    </asset>
    <worldbody>

    <body name="base_link" pos="0 0 0">
      <!--freejoint name="watt_base"/>
      <inertial pos="0 0 0" quat="0.707107 0 0 0.707107" mass="50.455" fullinertia="0.6022 1.7386 2.0296 -0.02364 -0.1197 -0.001544"/-->
      <geom pos="0 0 0.127" type="mesh" rgba="0 0 0 1" mesh="summit_xls_chassis"/>

      <joint name="base_x_slide_joint" type="slide" pos="0 0 0" axis="1 0 0" limited="true" range="-5 5" damping="15000"/>
      <joint name="base_y_slide_joint" type="slide" pos="0 0 0" axis="0 1 0" limited="true" range="-5 5" damping="15000"/>
      <joint name="base_z_hinge_joint" type="hinge" pos="0 0 0" axis="0 0 1" limited="true" range="-3.14 3.14" damping="10000"/>

    <body name="summit_xl_front_right_wheel_link" pos="0.2225 -0.2045 0.127">
      <inertial pos="0 0 0" quat="0.707107 0 0 0.707107" mass="6.5" diaginertia="0.0524193 0.0303095 0.0303095"/>
      <!--joint name="summit_xl_front_right_wheel_joint" pos="0 0 0" axis="0 1 0"/-->
      <geom size="0.127 0.0435" quat="0.707107 0.707107 0 0" type="cylinder" rgba="0.2 0.2 0.2 1"/>
    </body>
    <body name="summit_xl_front_left_wheel_link" pos="0.2225 0.2045 0.127">
      <inertial pos="0 0 0" quat="0.707107 0 0 0.707107" mass="6.5" diaginertia="0.0524193 0.0303095 0.0303095"/>
      <!--joint name="summit_xl_front_left_wheel_joint" pos="0 0 0" axis="0 1 0"/-->
      <geom size="0.127 0.0435" quat="0.707107 0.707107 0 0" type="cylinder" rgba="0.2 0.2 0.2 1"/>
    </body>
    <body name="summit_xl_back_left_wheel_link" pos="-0.2225 0.2045 0.127">
      <inertial pos="0 0 0" quat="0.707107 0 0 0.707107" mass="6.5" diaginertia="0.0524193 0.0303095 0.0303095"/>
      <!--joint name="summit_xl_back_left_wheel_joint" pos="0 0 0" axis="0 1 0"/-->
      <geom size="0.127 0.0435" quat="0.707107 0.707107 0 0" type="cylinder" rgba="0.2 0.2 0.2 1"/>
    </body>
    <body name="summit_xl_back_right_wheel_link" pos="-0.2225 -0.2045 0.127">
      <inertial pos="0 0 0" quat="0.707107 0 0 0.707107" mass="6.5" diaginertia="0.0524193 0.0303095 0.0303095"/>
      <!-- joint name="summit_xl_back_right_wheel_joint" pos="0 0 0" axis="0 1 0"/ -->
      <geom size="0.127 0.0435" quat="0.707107 0.707107 0 0" type="cylinder" rgba="0.2 0.2 0.2 1"/>
    </body>

        
        <!-- base?-->
        <body name="ur5e_base_link" pos="0.225 0 0.395">
        <inertial pos="0.0 0.0 0.0" quat="0.0 0.0 0.0 1.0" mass="4.0" diaginertia="0.00443333156 0.00443333156 0.0072" />

        <geom type="mesh" mesh="link0" rgba=".95 .99 .92 1" />
        <body name="ur5e_shoulder_link" pos="0.0 0 0.163">
            <inertial pos="0.0 0.0 0.0" quat="0.711549 0.00634377 -0.0131124 0.702485" mass="4.0" diaginertia="0.707137 0.703435 0.00852456" />
            <joint name="panda_joint1" pos="0 0 0" axis="0 0 1" limited="true" range="-2.8973 2.8973" damping="10" frictionloss="5" />
            <geom type="mesh" mesh="link1" rgba=".95 .99 .92 1" />
            <body name="panda_link2" pos="0 0 0" quat="0.707107 -0.707107 0 0">
                <inertial pos="-0.003141 -0.02872 0.003495" quat="-0.168175 0.828366 -0.122878 0.520027" mass="0.646926" diaginertia="0.0310326 0.0283001 0.00273425" />
                <joint name="panda_joint2" pos="0 0 0" axis="0 0 1" limited="true" range="-1.7628 1.7628" damping="5" frictionloss="2" />
                <geom type="mesh" mesh="link2" rgba=".95 .99 .92 1" />
                <body name="panda_link3" pos="0 -0.316 0" quat="0.707107 0.707107 0 0">
                    <inertial pos="0.027518 0.039252 -0.066502" quat="0.662769 -0.00678331 0.252053 0.705096" mass="3.2286" diaginertia="0.0415014 0.0414793 0.00124635" />
                    <joint name="panda_joint3" pos="0 0 0" axis="0 0 1" limited="true" range="-2.8973 2.8973" damping="5" frictionloss="2" />
                    <geom type="mesh" mesh="link3" rgba=".95 .99 .92 1" />
                    <body name="panda_link4" pos="0.0825 0 0" quat="0.707107 0.707107 0 0">
                        <inertial pos="-0.05317 0.104419 0.027454" quat="0.65058 0.529822 -0.0962034 0.535518" mass="3.5879" diaginertia="0.0349596 0.0281483 0.0106201" />
                        <joint name="panda_joint4" pos="0 0 0" axis="0 0 1" limited="true" range="-3.0718 -0.0698" damping="1" frictionloss="0.5" />
                        <geom type="mesh" mesh="link4" rgba=".95 .99 .92 1" />
                        <body name="panda_link5" pos="-0.0825 0.384 0" quat="0.707107 -0.707107 0 0">
                            <inertial pos="-0.011953 0.041065 -0.038437" quat="0.987313 -0.0121954 0.0719187 -0.141037" mass="1.22595" diaginertia="0.0367625 0.0288531 0.00803437" />
                            <joint name="panda_joint5" pos="0 0 0" axis="0 0 1" limited="true" range="-2.8973 2.8973" damping="2" frictionloss="1" />
                            <geom type="mesh" mesh="link5" rgba=".95 .99 .92 1" />
                            <body name="panda_link6" pos="0 0 0" quat="0.707107 0.707107 0 0">
                                <inertial pos="0.060149 -0.014117 -0.010517" quat="0.101075 0.59332 0.0287227 0.798079" mass="1.66656" diaginertia="0.00584276 0.00431037 0.00159787" />
                                <joint name="panda_joint6" pos="0 0 0" axis="0 0 1" limited="true" range="-0.0175 3.7525" damping="1" frictionloss="0.5" />
                                <geom type="mesh" mesh="link6" rgba=".95 .99 .92 1" />
                                <body name="panda_link7" pos="0.088 0 0" quat="0.707107 0.707107 0 0">
                                    <inertial pos="0.010517 -0.004252 0.061597" quat="0.992939 -0.0762041 0.0733595 -0.0537067" mass="0.735522" diaginertia="0.0127345 0.0101055 0.00451803" />
                                    <joint name="panda_joint7" pos="0 0 0" axis="0 0 1" limited="true" range="-2.8973 2.8973" damping="1" frictionloss="0.5" />
                                    
                                    <body name="ee" pos="0.0 0 0.0">
                                    <site name = "ee_site"  size = "0.01" rgba = ".1 .1 .9 1" type = "sphere" />
                                    <inertial pos="0.0 -0.0 -0.0" quat="0 0 0 1" mass="0.001" diaginertia="0.000254978 0.000183534 0.000157643" />
                                    <geom contype="1" conaffinity="1" condim="3" type="sphere" pos="0.0 0.0 0" size="0.05" rgba="0.792157 0.819608 0.933333 1"/>
                                    <site class="FTsensor" name="FTsensor" pos="0 0 0.05"/>
                                    </body>


                                </body>
                            </body>
                        </body>
                    </body>
                </body>
            </body>
        </body>
        </body>
        </body>

    </worldbody>
    <actuator>

        <!--position ctrllimited="true" ctrlrange="-10.0 10.0" joint="base_x_slide_joint" kp="18000" name="base_x_slide_joint" user="1"/>
        <position ctrllimited="true" ctrlrange="-10.0 10.0" joint="base_y_slide_joint" kp="18000" name="base_y_slide_joint" user="1"/>
        <position ctrllimited="true" ctrlrange="-0.57 0.57" kp="20000" joint="base_z_hinge_joint" name="base_z_hinge_joint" user="1"/-->
        <!-- <velocity name="base_x_slide_joint" joint="base_x_slide_joint"  kv="200" forcerange="-200 200" ctrlrange="-100.0 100.0"/> 
        <velocity name="base_y_slide_joint" joint="base_y_slide_joint" kv="200" forcerange="-200 200" ctrlrange="-100.0 100.0"/>
        <velocity name="base_z_hinge_joint" joint="base_z_hinge_joint"  kv="200" forcerange="-200 200" ctrlrange="-100.0 100.0"/>  -->


        <velocity name="base_x_slide_joint" joint="base_x_slide_joint"  kp="50000" forcerange="-2000 2000" ctrlrange="-10000.0 10000.0"/> 
        <velocity name="base_y_slide_joint" joint="base_y_slide_joint" kp="50000" forcerange="-2000 2000" ctrlrange="-10000.0 10000.0"/>
        <velocity name="base_z_hinge_joint" joint="base_z_hinge_joint"  kp="50000" forcerange="-2000 2000" ctrlrange="-10000.0 10000.0"/> 
        <position name="panda_joint1_Motor" joint="panda_joint1" kp="55000"  ctrllimited="false"/>
        <position name="panda_joint2_Motor" joint="panda_joint2" kp="55000"  ctrllimited="false"/>
        <position name="panda_joint3_Motor" joint="panda_joint3" kp="55000"  ctrllimited="false"/>
        <position name="panda_joint4_Motor" joint="panda_joint4" kp="55000"  ctrllimited="false"/>
        <position name="panda_joint5_Motor" joint="panda_joint5" kp="55000"  ctrllimited="false"/>
        <position name="panda_joint6_Motor" joint="panda_joint6" kp="55000"  ctrllimited="false"/>
        <position name="panda_joint7_Motor" joint="panda_joint7" kp="55000"  ctrllimited="false"/>
        


        <!-- <motor name="panda_joint1_Motor" joint="panda_joint1" forcerange="-200 200" ctrlrange="-200 200"/>
        <motor name="panda_joint2_Motor" joint="panda_joint2" forcerange="-200 200" ctrlrange="-200 200"/>
        <motor name="panda_joint3_Motor" joint="panda_joint3" forcerange="-200 200" ctrlrange="-200 200"/>
        <motor name="panda_joint4_Motor" joint="panda_joint4" forcerange="-200 200" ctrlrange="-200 200"/>
        <motor name="panda_joint5_Motor" joint="panda_joint5" forcerange="-200 200" ctrlrange="-200 200"/>
        <motor name="panda_joint6_Motor" joint="panda_joint6" forcerange="-200 200" ctrlrange="-200 200"/>
        <motor name="panda_joint7_Motor" joint="panda_joint7" forcerange="-200 200" ctrlrange="-200 200"/> -->
    </actuator>
    <sensor>
        <force name="force" site="FTsensor"/>
        <torque name="torque" site="FTsensor"/>
    </sensor>

    <!-- <keyframe>
    <key name="front" time="0" qpos ="0 0 0 0 0 0 -1.54 0 1.54 0" qvel ="0 0 0 0 0 0 0 0 0 0"/>									
    </keyframe> -->
</mujoco>

